Workbook

Sheet P1-WT
A1: Run 1 | G1: Run 2 | M1: Run 3
A2: Time (µs) | B2: Antiparallel | C2: Parallel | D2: Total | E2: % Antiparallel | G2: Time (µs) | H2: Antiparallel | I2: Parallel | J2: Total | K2: % Antiparallel | M2: Time (µs) | N2: Antiparallel | O2: Parallel | P2: Total | Q2: % Antiparallel
A3: 0.00609 | B3: 0 | C3: 0 | D3: =B3+C3 -> 0 | E3: 0 | G3: 0.00609 | H3: 0 | I3: 0 | J3: =H3+I3 -> 0 | K3: 0 | M3: 0.00609 | N3: 0 | O3: 0 | P3: =N3+O3 -> 0 | Q3: 0
A4: 0.00657 | B4: 0 | C4: 0 | D4: =B4+C4 -> 0 | E4: 0 | G4: 0.00657 | H4: 0 | I4: 0 | J4: =H4+I4 -> 0 | K4: 0 | M4: 0.00657 | N4: 0 | O4: 0 | P4: =N4+O4 -> 0 | Q4: 0
A5: 0.01273 | B5: 0 | C5: 0 | D5: =B5+C5 -> 0 | E5: 0 | G5: 0.01273 | H5: 0 | I5: 0 | J5: =H5+I5 -> 0 | K5: 0 | M5: 0.01274 | N5: 0 | O5: 0 | P5: =N5+O5 -> 0 | Q5: 0
A6: 0.0135 | B6: 0 | C6: 0 | D6: =B6+C6 -> 0 | E6: 0 | G6: 0.01348 | H6: 0 | I6: 0 | J6: =H6+I6 -> 0 | K6: 0 | M6: 0.0135 | N6: 0 | O6: 0 | P6: =N6+O6 -> 0 | Q6: 0
A7: 0.01974 | B7: 0 | C7: 0 | D7: =B7+C7 -> 0 | E7: 0 | G7: 0.01973 | H7: 0 | I7: 0 | J7: =H7+I7 -> 0 | K7: 0 | M7: 0.01975 | N7: 0 | O7: 0 | P7: =N7+O7 -> 0 | Q7: 0
A8: 0.02085 | B8: 0 | C8: 0 | D8: =B8+C8 -> 0 | E8: 0 | G8: 0.02084 | H8: 0 | I8: 0 | J8: =H8+I8 -> 0 | K8: 0 | M8: 0.02084 | N8: 0 | O8: 0 | P8: =N8+O8 -> 0 | Q8: 0
A9: 0.02719 | B9: 0 | C9: 0 | D9: =B9+C9 -> 0 | E9: 0 | G9: 0.02718 | H9: 0 | I9: 0 | J9: =H9+I9 -> 0 | K9: 0 | M9: 0.02719 | N9: 0 | O9: 0 | P9: =N9+O9 -> 0 | Q9: 0
A10: 0.02869 | B10: 0 | C10: 0 | D10: =B10+C10 -> 0 | E10: 0 | G10: 0.02868 | H10: 0 | I10: 0 | J10: =H10+I10 -> 0 | K10: 0 | M10: 0.02871 | N10: 0 | O10: 0 | P10: =N10+O10 -> 0 | Q10: 0
A11: 0.03516 | B11: 0 | C11: 0 | D11: =B11+C11 -> 0 | E11: 0 | G11: 0.03515 | H11: 0 | I11: 0 | J11: =H11+I11 -> 0 | K11: 0 | M11: 0.03518 | N11: 0 | O11: 0 | P11: =N11+O11 -> 0 | Q11: 0
A12: 0.03716 | B12: 0 | C12: 0 | D12: =B12+C12 -> 0 | E12: 0 | G12: 0.03716 | H12: 0 | I12: 0 | J12: =H12+I12 -> 0 | K12: 0 | M12: 0.03721 | N12: 0 | O12: 0 | P12: =N12+O12 -> 0 | Q12: 0
A13: 0.04369 | B13: 0 | C13: 0 | D13: =B13+C13 -> 0 | E13: 0 | G13: 0.04368 | H13: 0 | I13: 0 | J13: =H13+I13 -> 0 | K13: 0 | M13: 0.04374 | N13: 0 | O13: 0 | P13: =N13+O13 -> 0 | Q13: 0
A14: 0.05021 | B14: 0 | C14: 0 | D14: =B14+C14 -> 0 | E14: 0 | G14: 0.05021 | H14: 0 | I14: 0 | J14: =H14+I14 -> 0 | K14: 0 | M14: 0.05027 | N14: 0 | O14: 0 | P14: =N14+O14 -> 0 | Q14: 0
... A16: 0.05693 | B16: 0 | C16: 0 | D16: =B16+C16 -> 0 | E16: 0 | G16: 0.0569 | H16: 0 | I16: 0 | J16: =H16+I16 -> 0 | K16: 0 | M16: 0.05696 | N16: 0 | O16: 0 | P16: =N16+O16 -> 0 | Q16: 0
A17: 0.06352 | B17: 8 | C17: 0 | D17: =B17+C17 -> 8 | E17: =B17/D17*100 -> 100 | G17: 0.06349 | H17: 0 | I17: 0 | J17: =H17+I17 -> 0 | K17: 0 | M17: 0.06355 | N17: 0 | O17: 0 | P17: =N17+O17 -> 0 | Q17: 0
A18: 0.06399 | B18: 0 | C18: 0 | D18: =B18+C18 -> 0 | E18: 0 | G18: 0.06397 | H18: 0 | I18: 0 | J18: =H18+I18 -> 0 | K18: 0 | M18: 0.06403 | N18: 0 | O18: 0 | P18: =N18+O18 -> 0 | Q18: 0
A19: 0.07066 | B19: 0 | C19: 0 | D19: =B19+C19 -> 0 | E19: 0 | G19: 0.07064 | H19: 0 | I19: 0 | J19: =H19+I19 -> 0 | K19: 0 | M19: 0.07069 | N19: 0 | O19: 0 | P19: =N19+O19 -> 0 | Q19: 0
A20: 0.07732 | B20: 2 | C20: 0 | D20: =B20+C20 -> 2 | E20: =B20/D20*100 -> 100 | G20: 0.07731 | H20: 0 | I20: 0 | J20: =H20+I20 -> 0 | K20: 0 | M20: 0.07736 | N20: 0 | O20: 0 | P20: =N20+O20 -> 0 | Q20: 0
A21: 0.08292 | B21: 0 | C21: 0 | D21: =B21+C21 -> 0 | E21: 0 | G21: 0.08294 | H21: 0 | I21: 0 | J21: =H21+I21 -> 0 | K21: 0 | M21: 0.08297 | N21: 0 | O21: 0 | P21: =N21+O21 -> 0 | Q21: 0
A22: 0.08967 | B22: 0 | C22: 0 | D22: =B22+C22 -> 0 | E22: 0 | G22: 0.08969 | H22: 0 | I22: 0 | J22: =H22+I22 -> 0 | K22: 0 | M22: 0.08972 | N22: 10 | O22: 0 | P22: =N22+O22 -> 10 | Q22: =N22/P22*100 -> 100
A23: 0.09642 | B23: 10 | C23: 0 | D23: =B23+C23 -> 10 | E23: =B23/D23*100 -> 100 | G23: 0.09644 | H23: 4 | I23: 0 | J23: =H23+I23 -> 4 | K23: =H23/J23*100 -> 100 | M23: 0.09647 | N23: 4 | O23: 0 | P23: =N23+O23 -> 4 | Q23: =N23/P23*100 -> 100
A24: 0.10317 | B24: 4 | C24: 0 | D24: =B24+C24 -> 4 | E24: =B24/D24*100 -> 100 | G24: 0.10319 | H24: 0 | I24: 0 | J24: =H24+I24 -> 0 | K24: 0 | M24: 0.10322 | N24: 0 | O24: 0 | P24: =N24+O24 -> 0 | Q24: 0
A25: 0.10765 | B25: 4 | C25: 0 | D25: =B25+C25 -> 4 | E25: =B25/D25*100 -> 100 | G25: 0.10766 | H25: 8 | I25: 0 | J25: =H25+I25 -> 8 | K25: =H25/J25*100 -> 100 | M25: 0.10767 | N25: 0 | O25: 0 | P25: =N25+O25 -> 0 | Q25: 0
A26: 0.11457 | B26: 18 | C26: 8 | D26: =B26+C26 -> 26 | E26: =B26/D26*100 -> 69.230769 | G26: 0.11458 | H26: 6 | I26: 0 | J26: =H26+I26 -> 6 | K26: =H26/J26*100 -> 100 | M26: 0.11459 | N26: 15 | O26: 21 | P26: =N26+O26 -> 36 | Q26: =N26/P26*100 -> 41.666667
A27: 0.12149 | B27: 27 | C27: 4 | D27: =B27+C27 -> 31 | E27: =B27/D27*100 -> 87.096774 | G27: 0.1215 | H27: 14 | I27: 10 | J27: =H27+I27 -> 24 | K27: =H27/J27*100 -> 58.333333 | M27: 0.12151 | N27: 28 | O27: 47 | P27: =N27+O27 -> 75 | Q27: =N27/P27*100 -> 37.333333
A28: 0.12841 | B28: 8 | C28: 12 | D28: =B28+C28 -> 20 | E28: =B28/D28*100 -> 40 | G28: 0.12842 | H28: 8 | I28: 7 | J28: =H28+I28 -> 15 | K28: =H28/J28*100 -> 53.333333 | M28: 0.12843 | N28: 23 | O28: 52 | P28: =N28+O28 -> 75 | Q28: =N28/P28*100 -> 30.666667
A29: 0.13533 | B29: 22 | C29: 37 | D29: =B29+C29 -> 59 | E29: =B29/D29*100 -> 37.288136 | G29: 0.13534 | H29: 12 | I29: 40 | J29: =H29+I29 -> 52 | K29: =H29/J29*100 -> 23.076923 | M29: 0.13535 | N29: 19 | O29: 56 | P29: =N29+O29 -> 75 | Q29: =N29/P29*100 -> 25.333333
A30: 0.14225 | B30: 27 | C30: 17 | D30: =B30+C30 -> 44 | E30: =B30/D30*100 -> 61.363636 | G30: 0.14226 | H30: 30 | I30: 4 | J30: =H30+I30 -> 34 | K30: =H30/J30*100 -> 88.235294 | M30: 0.14227 | N30: 18 | O30: 97 | P30: =N30+O30 -> 115 | Q30: =N30/P30*100 -> 15.652174
A31: 0.14918 | B31: 4 | C31: 30 | D31: =B31+C31 -> 34 | E31: =B31/D31*100 -> 11.764706 | G31: 0.14918 | H31: 31 | I31: 15 | J31: =H31+I31 -> 46 | K31: =H31/J31*100 -> 67.391304 | M31: 0.14919 | N31: 19 | O31: 85 | P31: =N31+O31 -> 104 | Q31: =N31/P31*100 -> 18.269231
A32: 0.1561 | B32: 29 | C32: 35 | D32: =B32+C32 -> 64 | E32: =B32/D32*100 -> 45.3125 | G32: 0.1561 | H32: 12 | I32: 52 | J32: =H32+I32 -> 64 | K32: =H32/J32*100 -> 18.75 | M32: 0.15611 | N32: 23 | O32: 52 | P32: =N32+O32 -> 75 | Q32: =N32/P32*100 -> 30.666667
A33: 0.16302 | B33: 24 | C33: 13 | D33: =B33+C33 -> 37 | E33: =B33/D33*100 -> 64.864865 | G33: 0.16302 | H33: 12 | I33: 23 | J33: =H33+I33 -> 35 | K33: =H33/J33*100 -> 34.285714 | M33: 0.16303 | N33: 43 | O33: 55 | P33: =N33+O33 -> 98 | Q33: =N33/P33*100 -> 43.877551
A34: 0.16994 | B34: 25 | C34: 25 | D34: =B34+C34 -> 50 | E34: =B34/D34*100 -> 50 | G34: 0.16994 | H34: 28 | I34: 24 | J34: =H34+I34 -> 52 | K34: =H34/J34*100 -> 53.846154 | M34: 0.16995 | N34: 48 | O34: 23 | P34: =N34+O34 -> 71 | Q34: =N34/P34*100 -> 67.605634
A35: 0.17686 | B35: 26 | C35: 25 | D35: =B35+C35 -> 51 | E35: =B35/D35*100 -> 50.980392 | G35: 0.17686 | H35: 17 | I35: 30 | J35: =H35+I35 -> 47 | K35: =H35/J35*100 -> 36.170213 | M35: 0.17687 | N35: 35 | O35: 26 | P35: =N35+O35 -> 61 | Q35: =N35/P35*100 -> 57.377049
A36: 0.18378 | B36: 33 | C36: 9 | D36: =B36+C36 -> 42 | E36: =B36/D36*100 -> 78.571429 | G36: 0.18378 | H36: 31 | I36: 42 | J36: =H36+I36 -> 73 | K36: =H36/J36*100 -> 42.465753 | M36: 0.18379 | N36: 41 | O36: 29 | P36: =N36+O36 -> 70 | Q36: =N36/P36*100 -> 58.571429
A37: 0.1907 | B37: 26 | C37: 38 | D37: =B37+C37 -> 64 | E37: =B37/D37*100 -> 40.625 | G37: 0.1907 | H37: 6 | I37: 57 | J37: =H37+I37 -> 63 | K37: =H37/J37*100 -> 9.5238095 | M37: 0.19071 | N37: 26 | O37: 27 | P37: =N37+O37 -> 53 | Q37: =N37/P37*100 -> 49.056604
... A4825: 32.17628 | B4825: 28 | C4825: 478 | D4825: =B4825+C4825 -> 506 | E4825: =B4825/D4825*100 -> 5.5335968 | G4825: 32.153 | H4825: 33 | I4825: 410 | J4825: =H4825+I4825 -> 443 | K4825: =H4825/J4825*100 -> 7.4492099 | M4825: 32.09741 | N4825: 48 | O4825: 284 | P4825: =N4825+O4825 -> 332 | Q4825: =N4825/P4825*100 -> 14.457831

Sheet P1-L38M
A1: Run 1 | G1: Run 2 | M1: Run 3
A2: Time (µs) | B2: Antiparallel | C2: Parallel | D2: Total | E2: % Antiparallel | G2: Time (µs) | H2: Antiparallel | I2: Parallel | J2: Total | K2: % Antiparallel | M2: Time (µs) | N2: Antiparallel | O2: Parallel | P2: Total | Q2: % Antiparallel
A3: 0.00609 | B3: 0 | C3: 0 | D3: =B3+C3 -> 0 | E3: 0 | G3: 0.00609 | H3: 0 | I3: 0 | J3: =H3+I3 -> 0 | K3: 0 | M3: 0.00609 | N3: 0 | O3: 0 | P3: =N3+O3 -> 0 | Q3: 0
A4: 0.00662 | B4: 0 | C4: 0 | D4: =B4+C4 -> 0 | E4: 0 | G4: 0.00663 | H4: 0 | I4: 0 | J4: =H4+I4 -> 0 | K4: 0 | M4: 0.00662 | N4: 0 | O4: 0 | P4: =N4+O4 -> 0 | Q4: 0
A5: 0.01278 | B5: 0 | C5: 0 | D5: =B5+C5 -> 0 | E5: 0 | G5: 0.01279 | H5: 0 | I5: 0 | J5: =H5+I5 -> 0 | K5: 0 | M5: 0.01278 | N5: 0 | O5: 0 | P5: =N5+O5 -> 0 | Q5: 0
A6: 0.01358 | B6: 0 | C6: 0 | D6: =B6+C6 -> 0 | E6: 0 | G6: 0.0136 | H6: 0 | I6: 0 | J6: =H6+I6 -> 0 | K6: 0 | M6: 0.01358 | N6: 0 | O6: 0 | P6: =N6+O6 -> 0 | Q6: 0
A7: 0.01983 | B7: 0 | C7: 0 | D7: =B7+C7 -> 0 | E7: 0 | G7: 0.01985 | H7: 0 | I7: 0 | J7: =H7+I7 -> 0 | K7: 0 | M7: 0.01983 | N7: 0 | O7: 0 | P7: =N7+O7 -> 0 | Q7: 0
A8: 0.021 | B8: 0 | C8: 0 | D8: =B8+C8 -> 0 | E8: 0 | G8: 0.02098 | H8: 0 | I8: 0 | J8: =H8+I8 -> 0 | K8: 0 | M8: 0.02098 | N8: 0 | O8: 0 | P8: =N8+O8 -> 0 | Q8: 0
A9: 0.02735 | B9: 0 | C9: 0 | D9: =B9+C9 -> 0 | E9: 0 | G9: 0.02733 | H9: 0 | I9: 0 | J9: =H9+I9 -> 0 | K9: 0 | M9: 0.02733 | N9: 0 | O9: 0 | P9: =N9+O9 -> 0 | Q9: 0
A10: 0.02892 | B10: 0 | C10: 0 | D10: =B10+C10 -> 0 | E10: 0 | G10: 0.02888 | H10: 0 | I10: 0 | J10: =H10+I10 -> 0 | K10: 0 | M10: 0.02889 | N10: 0 | O10: 0 | P10: =N10+O10 -> 0 | Q10: 0
A11: 0.03539 | B11: 0 | C11: 0 | D11: =B11+C11 -> 0 | E11: 0 | G11: 0.03535 | H11: 0 | I11: 0 | J11: =H11+I11 -> 0 | K11: 0 | M11: 0.03536 | N11: 0 | O11: 0 | P11: =N11+O11 -> 0 | Q11: 0
A12: 0.03745 | B12: 0 | C12: 0 | D12: =B12+C12 -> 0 | E12: 0 | G12: 0.03742 | H12: 0 | I12: 0 | J12: =H12+I12 -> 0 | K12: 0 | M12: 0.03744 | N12: 0 | O12: 0 | P12: =N12+O12 -> 0 | Q12: 0
A13: 0.04398 | B13: 0 | C13: 0 | D13: =B13+C13 -> 0 | E13: 0 | G13: 0.04395 | H13: 4 | I13: 0 | J13: =H13+I13 -> 4 | K13: =H13/J13*100 -> 100 | M13: 0.04397 | N13: 0 | O13: 0 | P13: =N13+O13 -> 0 | Q13: 0
A14: 0.05051 | B14: 0 | C14: 0 | D14: =B14+C14 -> 0 | E14: 0 | G14: 0.05048 | H14: 0 | I14: 0 | J14: =H14+I14 -> 0 | K14: 0 | M14: 0.0505 | N14: 0 | O14: 0 | P14: =N14+O14 -> 0 | Q14: 0
A15: 0.05069 | B15: 0 | C15: 0 | D15: =B15+C15 -> 0 | E15: 0 | G15: 0.05065 | H15: 0 | I15: 0 | J15: =H15+I15 -> 0 | K15: 0 | M15: 0.0507 | N15: 0 | O15: 0 | P15: =N15+O15 -> 0 | Q15: 0
A16: 0.05728 | B16: 0 | C16: 0 | D16: =B16+C16 -> 0 | E16: 0 | G16: 0.05724 | H16: 0 | I16: 0 | J16: =H16+I16 -> 0 | K16: 0 | M16: 0.0573 | N16: 0 | O16: 0 | P16: =N16+O16 -> 0 | Q16: 0
A17: 0.06387 | B17: 0 | C17: 0 | D17: =B17+C17 -> 0 | E17: 0 | G17: 0.06384 | H17: 0 | I17: 0 | J17: =H17+I17 -> 0 | K17: 0 | M17: 0.06389 | N17: 0 | O17: 0 | P17: =N17+O17 -> 0 | Q17: 0
A18: 0.06444 | B18: 0 | C18: 0 | D18: =B18+C18 -> 0 | E18: 0 | G18: 0.0644 | H18: 2 | I18: 0 | J18: =H18+I18 -> 2 | K18: =H18/J18*100 -> 100 | M18: 0.06446 | N18: 0 | O18: 0 | P18: =N18+O18 -> 0 | Q18: 0
A19: 0.07111 | B19: 0 | C19: 0 | D19: =B19+C19 -> 0 | E19: 0 | G19: 0.07107 | H19: 0 | I19: 0 | J19: =H19+I19 -> 0 | K19: 0 | M19: 0.07113 | N19: 4 | O19: 0 | P19: =N19+O19 -> 4 | Q19: =N19/P19*100 -> 100
A20: 0.07777 | B20: 6 | C20: 0 | D20: =B20+C20 -> 6 | E20: =B20/D20*100 -> 100 | G20: 0.07774 | H20: 4 | I20: 0 | J20: =H20+I20 -> 4 | K20: =H20/J20*100 -> 100 | M20: 0.07779 | N20: 4 | O20: 0 | P20: =N20+O20 -> 4 | Q20: =N20/P20*100 -> 100
A21: 0.08352 | B21: 8 | C21: 0 | D21: =B21+C21 -> 8 | E21: =B21/D21*100 -> 100 | G21: 0.08347 | H21: 0 | I21: 0 | J21: =H21+I21 -> 0 | K21: 0 | M21: 0.08356 | N21: 0 | O21: 0 | P21: =N21+O21 -> 0 | Q21: 0
A22: 0.09027 | B22: 4 | C22: 0 | D22: =B22+C22 -> 4 | E22: =B22/D22*100 -> 100 | G22: 0.09022 | H22: 4 | I22: 0 | J22: =H22+I22 -> 4 | K22: =H22/J22*100 -> 100 | M22: 0.09031 | N22: 0 | O22: 0 | P22: =N22+O22 -> 0 | Q22: 0
A23: 0.09702 | B23: 2 | C23: 0 | D23: =B23+C23 -> 2 | E23: =B23/D23*100 -> 100 | G23: 0.09697 | H23: 10 | I23: 0 | J23: =H23+I23 -> 10 | K23: =H23/J23*100 -> 100 | M23: 0.09706 | N23: 0 | O23: 0 | P23: =N23+O23 -> 0 | Q23: 0
A24: 0.10377 | B24: 4 | C24: 0 | D24: =B24+C24 -> 4 | E24: =B24/D24*100 -> 100 | G24: 0.10372 | H24: 8 | I24: 0 | J24: =H24+I24 -> 8 | K24: =H24/J24*100 -> 100 | M24: 0.10381 | N24: 0 | O24: 4 | P24: =N24+O24 -> 4 | Q24: =N24/P24*100 -> 0
A25: 0.10837 | B25: 4 | C25: 0 | D25: =B25+C25 -> 4 | E25: =B25/D25*100 -> 100 | G25: 0.10837 | H25: 4 | I25: 0 | J25: =H25+I25 -> 4 | K25: =H25/J25*100 -> 100 | M25: 0.10841 | N25: 0 | O25: 0 | P25: =N25+O25 -> 0 | Q25: 0
A26: 0.11529 | B26: 14 | C26: 6 | D26: =B26+C26 -> 20 | E26: =B26/D26*100 -> 70 | G26: 0.11529 | H26: 10 | I26: 0 | J26: =H26+I26 -> 10 | K26: =H26/J26*100 -> 100 | M26: 0.11533 | N26: 2 | O26: 0 | P26: =N26+O26 -> 2 | Q26: =N26/P26*100 -> 100
A27: 0.12221 | B27: 15 | C27: 4 | D27: =B27+C27 -> 19 | E27: =B27/D27*100 -> 78.947368 | G27: 0.12221 | H27: 10 | I27: 4 | J27: =H27+I27 -> 14 | K27: =H27/J27*100 -> 71.428571 | M27: 0.12225 | N27: 4 | O27: 0 | P27: =N27+O27 -> 4 | Q27: =N27/P27*100 -> 100
A28: 0.12913 | B28: 16 | C28: 12 | D28: =B28+C28 -> 28 | E28: =B28/D28*100 -> 57.142857 | G28: 0.12913 | H28: 4 | I28: 4 | J28: =H28+I28 -> 8 | K28: =H28/J28*100 -> 50 | M28: 0.12917 | N28: 32 | O28: 11 | P28: =N28+O28 -> 43 | Q28: =N28/P28*100 -> 74.418605
A29: 0.13605 | B29: 17 | C29: 6 | D29: =B29+C29 -> 23 | E29: =B29/D29*100 -> 73.913043 | G29: 0.13605 | H29: 40 | I29: 3 | J29: =H29+I29 -> 43 | K29: =H29/J29*100 -> 93.023256 | M29: 0.13609 | N29: 9 | O29: 29 | P29: =N29+O29 -> 38 | Q29: =N29/P29*100 -> 23.684211
A30: 0.14297 | B30: 34 | C30: 11 | D30: =B30+C30 -> 45 | E30: =B30/D30*100 -> 75.555556 | G30: 0.14297 | H30: 34 | I30: 43 | J30: =H30+I30 -> 77 | K30: =H30/J30*100 -> 44.155844 | M30: 0.14301 | N30: 6 | O30: 9 | P30: =N30+O30 -> 15 | Q30: =N30/P30*100 -> 40
A31: 0.14989 | B31: 14 | C31: 10 | D31: =B31+C31 -> 24 | E31: =B31/D31*100 -> 58.333333 | G31: 0.14989 | H31: 43 | I31: 65 | J31: =H31+I31 -> 108 | K31: =H31/J31*100 -> 39.814815 | M31: 0.14993 | N31: 41 | O31: 28 | P31: =N31+O31 -> 69 | Q31: =N31/P31*100 -> 59.42029
A32: 0.15681 | B32: 14 | C32: 7 | D32: =B32+C32 -> 21 | E32: =B32/D32*100 -> 66.666667 | G32: 0.15681 | H32: 31 | I32: 62 | J32: =H32+I32 -> 93 | K32: =H32/J32*100 -> 33.333333 | M32: 0.15685 | N32: 42 | O32: 4 | P32: =N32+O32 -> 46 | Q32: =N32/P32*100 -> 91.304348
A33: 0.16373 | B33: 25 | C33: 15 | D33: =B33+C33 -> 40 | E33: =B33/D33*100 -> 62.5 | G33: 0.16373 | H33: 41 | I33: 58 | J33: =H33+I33 -> 99 | K33: =H33/J33*100 -> 41.414141 | M33: 0.16377 | N33: 55 | O33: 16 | P33: =N33+O33 -> 71 | Q33: =N33/P33*100 -> 77.464789
A34: 0.17065 | B34: 36 | C34: 21 | D34: =B34+C34 -> 57 | E34: =B34/D34*100 -> 63.157895 | G34: 0.17065 | H34: 35 | I34: 62 | J34: =H34+I34 -> 97 | K34: =H34/J34*100 -> 36.082474 | M34: 0.17069 | N34: 24 | O34: 15 | P34: =N34+O34 -> 39 | Q34: =N34/P34*100 -> 61.538462
A35: 0.17757 | B35: 49 | C35: 11 | D35: =B35+C35 -> 60 | E35: =B35/D35*100 -> 81.666667 | G35: 0.17757 | H35: 40 | I35: 78 | J35: =H35+I35 -> 118 | K35: =H35/J35*100 -> 33.898305 | M35: 0.17762 | N35: 38 | O35: 17 | P35: =N35+O35 -> 55 | Q35: =N35/P35*100 -> 69.090909
A36: 0.18449 | B36: 34 | C36: 20 | D36: =B36+C36 -> 54 | E36: =B36/D36*100 -> 62.962963 | G36: 0.18449 | H36: 12 | I36: 97 | J36: =H36+I36 -> 109 | K36: =H36/J36*100 -> 11.009174 | M36: 0.18454 | N36: 22 | O36: 31 | P36: =N36+O36 -> 53 | Q36: =N36/P36*100 -> 41.509434
A37: 0.19141 | B37: 19 | C37: 23 | D37: =B37+C37 -> 42 | E37: =B37/D37*100 -> 45.238095 | G37: 0.19141 | H37: 10 | I37: 61 | J37: =H37+I37 -> 71 | K37: =H37/J37*100 -> 14.084507 | M37: 0.19146 | N37: 28 | O37: 58 | P37: =N37+O37 -> 86 | Q37: =N37/P37*100 -> 32.55814
... A4825: 32.31271 | B4825: 127 | C4825: 242 | D4825: =B4825+C4825 -> 369 | E4825: =B4825/D4825*100 -> 34.417344 | G4825: 32.30476 | H4825: 68 | I4825: 278 | J4825: =H4825+I4825 -> 346 | K4825: =H4825/J4825*100 -> 19.653179 | M4825: 32.3013 | N4825: 107 | O4825: 165 | P4825: =N4825+O4825 -> 272 | Q4825: =N4825/P4825*100 -> 39.338235

Sheet P1-L38A
A1: Run 1 | G1: Run 2 | M1: Run 3
A2: Time (µs) | B2: Antiparallel | C2: Parallel | D2: Total | E2: % Antiparallel | G2: Time (µs) | H2: Antiparallel | I2: Parallel | J2: Total | K2: % Antiparallel | M2: Time (µs) | N2: Antiparallel | O2: Parallel | P2: Total | Q2: % Antiparallel
A3: 0.00609 | B3: 0 | C3: 0 | D3: =B3+C3 -> 0 | E3: 0 | G3: 0.00609 | H3: 0 | I3: 0 | J3: =H3+I3 -> 0 | K3: 0 | M3: 0.00609 | N3: 0 | O3: 0 | P3: =N3+O3 -> 0 | Q3: 0
A4: 0.00639 | B4: 0 | C4: 0 | D4: =B4+C4 -> 0 | E4: 0 | G4: 0.0064 | H4: 0 | I4: 0 | J4: =H4+I4 -> 0 | K4: 0 | M4: 0.00639 | N4: 0 | O4: 0 | P4: =N4+O4 -> 0 | Q4: 0
A5: 0.01255 | B5: 0 | C5: 0 | D5: =B5+C5 -> 0 | E5: 0 | G5: 0.01256 | H5: 0 | I5: 0 | J5: =H5+I5 -> 0 | K5: 0 | M5: 0.01255 | N5: 0 | O5: 0 | P5: =N5+O5 -> 0 | Q5: 0
A6: 0.01313 | B6: 0 | C6: 0 | D6: =B6+C6 -> 0 | E6: 0 | G6: 0.01314 | H6: 4 | I6: 0 | J6: =H6+I6 -> 4 | K6: =H6/J6*100 -> 100 | M6: 0.01313 | N6: 0 | O6: 0 | P6: =N6+O6 -> 0 | Q6: 0
A7: 0.01937 | B7: 0 | C7: 0 | D7: =B7+C7 -> 0 | E7: 0 | G7: 0.01939 | H7: 0 | I7: 0 | J7: =H7+I7 -> 0 | K7: 0 | M7: 0.01938 | N7: 0 | O7: 0 | P7: =N7+O7 -> 0 | Q7: 0
A8: 0.02027 | B8: 0 | C8: 0 | D8: =B8+C8 -> 0 | E8: 0 | G8: 0.02029 | H8: 0 | I8: 0 | J8: =H8+I8 -> 0 | K8: 0 | M8: 0.02028 | N8: 0 | O8: 0 | P8: =N8+O8 -> 0 | Q8: 0
A9: 0.02661 | B9: 0 | C9: 0 | D9: =B9+C9 -> 0 | E9: 0 | G9: 0.02664 | H9: 0 | I9: 0 | J9: =H9+I9 -> 0 | K9: 0 | M9: 0.02663 | N9: 0 | O9: 0 | P9: =N9+O9 -> 0 | Q9: 0
A10: 0.02792 | B10: 0 | C10: 0 | D10: =B10+C10 -> 0 | E10: 0 | G10: 0.02791 | H10: 0 | I10: 0 | J10: =H10+I10 -> 0 | K10: 0 | M10: 0.02791 | N10: 0 | O10: 0 | P10: =N10+O10 -> 0 | Q10: 0
A11: 0.03438 | B11: 0 | C11: 0 | D11: =B11+C11 -> 0 | E11: 0 | G11: 0.03438 | H11: 0 | I11: 0 | J11: =H11+I11 -> 0 | K11: 0 | M11: 0.03438 | N11: 0 | O11: 0 | P11: =N11+O11 -> 0 | Q11: 0
A12: 0.03615 | B12: 0 | C12: 0 | D12: =B12+C12 -> 0 | E12: 0 | G12: 0.03618 | H12: 4 | I12: 0 | J12: =H12+I12 -> 4 | K12: =H12/J12*100 -> 100 | M12: 0.03615 | N12: 0 | O12: 0 | P12: =N12+O12 -> 0 | Q12: 0
A13: 0.04268 | B13: 0 | C13: 0 | D13: =B13+C13 -> 0 | E13: 0 | G13: 0.0427 | H13: 0 | I13: 0 | J13: =H13+I13 -> 0 | K13: 0 | M13: 0.04267 | N13: 0 | O13: 0 | P13: =N13+O13 -> 0 | Q13: 0
A14: 0.04895 | B14: 0 | C14: 0 | D14: =B14+C14 -> 0 | E14: 0 | G14: 0.04898 | H14: 0 | I14: 4 | J14: =H14+I14 -> 4 | K14: =H14/J14*100 -> 0 | M14: 0.04895 | N14: 0 | O14: 0 | P14: =N14+O14 -> 0 | Q14: 0
A15: 0.05554 | B15: 0 | C15: 0 | D15: =B15+C15 -> 0 | E15: 0 | G15: 0.05557 | H15: 0 | I15: 0 | J15: =H15+I15 -> 0 | K15: 0 | M15: 0.05555 | N15: 0 | O15: 0 | P15: =N15+O15 -> 0 | Q15: 0
A16: 0.06213 | B16: 0 | C16: 0 | D16: =B16+C16 -> 0 | E16: 0 | G16: 0.06216 | H16: 0 | I16: 0 | J16: =H16+I16 -> 0 | K16: 0 | M16: 0.06214 | N16: 0 | O16: 0 | P16: =N16+O16 -> 0 | Q16: 0
A17: 0.06221 | B17: 0 | C17: 0 | D17: =B17+C17 -> 0 | E17: 0 | G17: 0.06226 | H17: 0 | I17: 0 | J17: =H17+I17 -> 0 | K17: 0 | M17: 0.06222 | N17: 0 | O17: 0 | P17: =N17+O17 -> 0 | Q17: 0
A18: 0.06888 | B18: 4 | C18: 0 | D18: =B18+C18 -> 4 | E18: =B18/D18 -> 1 | G18: 0.06893 | H18: 0 | I18: 0 | J18: =H18+I18 -> 0 | K18: 0 | M18: 0.06889 | N18: 4 | O18: 5 | P18: =N18+O18 -> 9 | Q18: =N18/P18*100 -> 44.444444
A19: 0.07555 | B19: 0 | C19: 0 | D19: =B19+C19 -> 0 | E19: 0 | G19: 0.0756 | H19: 0 | I19: 0 | J19: =H19+I19 -> 0 | K19: 0 | M19: 0.07556 | N19: 0 | O19: 0 | P19: =N19+O19 -> 0 | Q19: 0
A20: 0.08063 | B20: 0 | C20: 0 | D20: =B20+C20 -> 0 | E20: 0 | G20: 0.08067 | H20: 0 | I20: 0 | J20: =H20+I20 -> 0 | K20: 0 | M20: 0.08065 | N20: 0 | O20: 0 | P20: =N20+O20 -> 0 | Q20: 0
A21: 0.08738 | B21: 0 | C21: 6 | D21: =B21+C21 -> 6 | E21: =B21/D21 -> 0 | G21: 0.08742 | H21: 8 | I21: 0 | J21: =H21+I21 -> 8 | K21: =H21/J21*100 -> 100 | M21: 0.0874 | N21: 0 | O21: 0 | P21: =N21+O21 -> 0 | Q21: 0
A22: 0.09413 | B22: 0 | C22: 0 | D22: =B22+C22 -> 0 | E22: 0 | G22: 0.09417 | H22: 0 | I22: 4 | J22: =H22+I22 -> 4 | K22: =H22/J22*100 -> 0 | M22: 0.09415 | N22: 8 | O22: 0 | P22: =N22+O22 -> 8 | Q22: =N22/P22*100 -> 100
A23: 0.10088 | B23: 4 | C23: 4 | D23: =B23+C23 -> 8 | E23: =B23/D23*100 -> 50 | G23: 0.10092 | H23: 4 | I23: 0 | J23: =H23+I23 -> 4 | K23: =H23/J23*100 -> 100 | M23: 0.1009 | N23: 12 | O23: 0 | P23: =N23+O23 -> 12 | Q23: =N23/P23*100 -> 100
A24: 0.10465 | B24: 0 | C24: 0 | D24: =B24+C24 -> 0 | E24: 0 | G24: 0.10471 | H24: 0 | I24: 0 | J24: =H24+I24 -> 0 | K24: 0 | M24: 0.10468 | N24: 4 | O24: 0 | P24: =N24+O24 -> 4 | Q24: =N24/P24*100 -> 100
A25: 0.11157 | B25: 12 | C25: 8 | D25: =B25+C25 -> 20 | E25: =B25/D25*100 -> 60 | G25: 0.11163 | H25: 5 | I25: 0 | J25: =H25+I25 -> 5 | K25: =H25/J25*100 -> 100 | M25: 0.1116 | N25: 15 | O25: 5 | P25: =N25+O25 -> 20 | Q25: =N25/P25*100 -> 75
A26: 0.11849 | B26: 10 | C26: 9 | D26: =B26+C26 -> 19 | E26: =B26/D26*100 -> 52.631579 | G26: 0.11855 | H26: 4 | I26: 6 | J26: =H26+I26 -> 10 | K26: =H26/J26*100 -> 40 | M26: 0.11852 | N26: 8 | O26: 10 | P26: =N26+O26 -> 18 | Q26: =N26/P26*100 -> 44.444444
A27: 0.12541 | B27: 8 | C27: 39 | D27: =B27+C27 -> 47 | E27: =B27/D27*100 -> 17.021277 | G27: 0.12547 | H27: 2 | I27: 8 | J27: =H27+I27 -> 10 | K27: =H27/J27*100 -> 20 | M27: 0.12544 | N27: 12 | O27: 4 | P27: =N27+O27 -> 16 | Q27: =N27/P27*100 -> 75
A28: 0.13233 | B28: 16 | C28: 19 | D28: =B28+C28 -> 35 | E28: =B28/D28*100 -> 45.714286 | G28: 0.13239 | H28: 13 | I28: 4 | J28: =H28+I28 -> 17 | K28: =H28/J28*100 -> 76.470588 | M28: 0.13236 | N28: 20 | O28: 10 | P28: =N28+O28 -> 30 | Q28: =N28/P28*100 -> 66.666667
A29: 0.13925 | B29: 4 | C29: 6 | D29: =B29+C29 -> 10 | E29: =B29/D29*100 -> 40 | G29: 0.13931 | H29: 10 | I29: 20 | J29: =H29+I29 -> 30 | K29: =H29/J29*100 -> 33.333333 | M29: 0.13928 | N29: 4 | O29: 6 | P29: =N29+O29 -> 10 | Q29: =N29/P29*100 -> 40
A30: 0.14617 | B30: 12 | C30: 4 | D30: =B30+C30 -> 16 | E30: =B30/D30*100 -> 75 | G30: 0.14623 | H30: 13 | I30: 16 | J30: =H30+I30 -> 29 | K30: =H30/J30*100 -> 44.827586 | M30: 0.1462 | N30: 31 | O30: 0 | P30: =N30+O30 -> 31 | Q30: =N30/P30*100 -> 100
A31: 0.15309 | B31: 4 | C31: 9 | D31: =B31+C31 -> 13 | E31: =B31/D31*100 -> 30.769231 | G31: 0.15315 | H31: 8 | I31: 10 | J31: =H31+I31 -> 18 | K31: =H31/J31*100 -> 44.444444 | M31: 0.15312 | N31: 10 | O31: 0 | P31: =N31+O31 -> 10 | Q31: =N31/P31*100 -> 100
A32: 0.16001 | B32: 22 | C32: 14 | D32: =B32+C32 -> 36 | E32: =B32/D32*100 -> 61.111111 | G32: 0.16007 | H32: 12 | I32: 0 | J32: =H32+I32 -> 12 | K32: =H32/J32*100 -> 100 | M32: 0.16004 | N32: 8 | O32: 4 | P32: =N32+O32 -> 12 | Q32: =N32/P32*100 -> 66.666667
A33: 0.16693 | B33: 8 | C33: 0 | D33: =B33+C33 -> 8 | E33: =B33/D33*100 -> 100 | G33: 0.16699 | H33: 14 | I33: 4 | J33: =H33+I33 -> 18 | K33: =H33/J33*100 -> 77.777778 | M33: 0.16696 | N33: 4 | O33: 6 | P33: =N33+O33 -> 10 | Q33: =N33/P33*100 -> 40
A34: 0.17385 | B34: 26 | C34: 0 | D34: =B34+C34 -> 26 | E34: =B34/D34*100 -> 100 | G34: 0.17391 | H34: 12 | I34: 19 | J34: =H34+I34 -> 31 | K34: =H34/J34*100 -> 38.709677 | M34: 0.17388 | N34: 22 | O34: 0 | P34: =N34+O34 -> 22 | Q34: =N34/P34*100 -> 100
A35: 0.18077 | B35: 12 | C35: 15 | D35: =B35+C35 -> 27 | E35: =B35/D35*100 -> 44.444444 | G35: 0.18083 | H35: 22 | I35: 0 | J35: =H35+I35 -> 22 | K35: =H35/J35*100 -> 100 | M35: 0.1808 | N35: 16 | O35: 12 | P35: =N35+O35 -> 28 | Q35: =N35/P35*100 -> 57.142857
A36: 0.18769 | B36: 18 | C36: 9 | D36: =B36+C36 -> 27 | E36: =B36/D36*100 -> 66.666667 | G36: 0.18775 | H36: 14 | I36: 0 | J36: =H36+I36 -> 14 | K36: =H36/J36*100 -> 100 | M36: 0.18772 | N36: 28 | O36: 10 | P36: =N36+O36 -> 38 | Q36: =N36/P36*100 -> 73.684211
... A43: 0.22941 | B43: 14 | C43: 8 | D43: =B43+C43 -> 22 | E43: =B43/D43*100 -> 63.636364 | G43: 0.22945 | H43: 22 | I43: 9 | J43: =H43+I43 -> 31 | K43: =H43/J43*100 -> 70.967742 | M43: 0.22943 | N43: 28 | O43: 0 | P43: =N43+O43 -> 28 | Q43: =N43/P43*100 -> 100
A44: 0.23633 | B44: 0 | C44: 0 | D44: =B44+C44 -> 0 | E44: 0 | G44: 0.23637 | H44: 6 | I44: 9 | J44: =H44+I44 -> 15 | K44: =H44/J44*100 -> 40 | M44: 0.23635 | N44: 0 | O44: 0 | P44: =N44+O44 -> 0 | Q44: 0
A45: 0.24325 | B45: 14 | C45: 4 | D45: =B45+C45 -> 18 | E45: =B45/D45*100 -> 77.777778 | G45: 0.24329 | H45: 19 | I45: 4 | J45: =H45+I45 -> 23 | K45: =H45/J45*100 -> 82.608696 | M45: 0.24327 | N45: 20 | O45: 4 | P45: =N45+O45 -> 24 | Q45: =N45/P45*100 -> 83.333333
A46: 0.25017 | B46: 8 | C46: 4 | D46: =B46+C46 -> 12 | E46: =B46/D46*100 -> 66.666667 | G46: 0.25021 | H46: 15 | I46: 7 | J46: =H46+I46 -> 22 | K46: =H46/J46*100 -> 68.181818 | M46: 0.25019 | N46: 0 | O46: 0 | P46: =N46+O46 -> 0 | Q46: 0
...

Sheet P1-V40A
A1: Run 1 | G1: Run 2 | M1: Run 3
A2: Time (µs) | B2: Antiparallel | C2: Parallel | D2: Total | E2: % Antiparallel | G2: Time (µs) | H2: Antiparallel | I2: Parallel | J2: Total | K2: % Antiparallel | M2: Time (µs) | N2: Antiparallel | O2: Parallel | P2: Total | Q2: % Antiparallel
A3: 0.00609 | B3: 0 | C3: 0 | D3: =B3+C3 -> 0 | E3: 0 | G3: 0.00609 | H3: 0 | I3: 0 | J3: =H3+I3 -> 0 | K3: 0 | M3: 0.00609 | N3: 0 | O3: 0 | P3: =N3+O3 -> 0 | Q3: 0
A4: 0.00645 | B4: 0 | C4: 0 | D4: =B4+C4 -> 0 | E4: 0 | G4: 0.00646 | H4: 0 | I4: 0 | J4: =H4+I4 -> 0 | K4: 0 | M4: 0.00645 | N4: 0 | O4: 0 | P4: =N4+O4 -> 0 | Q4: 0
A5: 0.01262 | B5: 0 | C5: 0 | D5: =B5+C5 -> 0 | E5: 0 | G5: 0.01262 | H5: 0 | I5: 0 | J5: =H5+I5 -> 0 | K5: 0 | M5: 0.01261 | N5: 0 | O5: 0 | P5: =N5+O5 -> 0 | Q5: 0
A6: 0.01326 | B6: 0 | C6: 0 | D6: =B6+C6 -> 0 | E6: 0 | G6: 0.01326 | H6: 0 | I6: 0 | J6: =H6+I6 -> 0 | K6: 0 | M6: 0.01325 | N6: 0 | O6: 0 | P6: =N6+O6 -> 0 | Q6: 0
A7: 0.01951 | B7: 0 | C7: 0 | D7: =B7+C7 -> 0 | E7: 0 | G7: 0.01951 | H7: 0 | I7: 0 | J7: =H7+I7 -> 0 | K7: 0 | M7: 0.0195 | N7: 0 | O7: 0 | P7: =N7+O7 -> 0 | Q7: 0
A8: 0.02047 | B8: 0 | C8: 0 | D8: =B8+C8 -> 0 | E8: 0 | G8: 0.02048 | H8: 0 | I8: 0 | J8: =H8+I8 -> 0 | K8: 0 | M8: 0.02047 | N8: 0 | O8: 0 | P8: =N8+O8 -> 0 | Q8: 0
A9: 0.02682 | B9: 0 | C9: 0 | D9: =B9+C9 -> 0 | E9: 0 | G9: 0.02682 | H9: 0 | I9: 0 | J9: =H9+I9 -> 0 | K9: 0 | M9: 0.02682 | N9: 0 | O9: 0 | P9: =N9+O9 -> 0 | Q9: 0
A10: 0.02818 | B10: 4 | C10: 0 | D10: =B10+C10 -> 4 | E10: =B10/D10*100 -> 100 | G10: 0.02819 | H10: 0 | I10: 0 | J10: =H10+I10 -> 0 | K10: 0 | M10: 0.02818 | N10: 0 | O10: 0 | P10: =N10+O10 -> 0 | Q10: 0
A11: 0.03465 | B11: 0 | C11: 0 | D11: =B11+C11 -> 0 | E11: 0 | G11: 0.03466 | H11: 0 | I11: 0 | J11: =H11+I11 -> 0 | K11: 0 | M11: 0.03465 | N11: 0 | O11: 0 | P11: =N11+O11 -> 0 | Q11: 0
A12: 0.0365 | B12: 0 | C12: 0 | D12: =B12+C12 -> 0 | E12: 0 | G12: 0.03652 | H12: 0 | I12: 0 | J12: =H12+I12 -> 0 | K12: 0 | M12: 0.0365 | N12: 0 | O12: 0 | P12: =N12+O12 -> 0 | Q12: 0
A13: 0.04303 | B13: 0 | C13: 0 | D13: =B13+C13 -> 0 | E13: 0 | G13: 0.04305 | H13: 4 | I13: 0 | J13: =H13+I13 -> 4 | K13: =H13/J13*100 -> 100 | M13: 0.04303 | N13: 4 | O13: 0 | P13: =N13+O13 -> 4 | Q13: =N13/P13*100 -> 100
A14: 0.04944 | B14: 0 | C14: 0 | D14: =B14+C14 -> 0 | E14: 0 | G14: 0.04946 | H14: 0 | I14: 0 | J14: =H14+I14 -> 0 | K14: 0 | M14: 0.04942 | N14: 4 | O14: 0 | P14: =N14+O14 -> 4 | Q14: =N14/P14*100 -> 100
A15: 0.05604 | B15: 0 | C15: 0 | D15: =B15+C15 -> 0 | E15: 0 | G15: 0.05606 | H15: 0 | I15: 0 | J15: =H15+I15 -> 0 | K15: 0 | M15: 0.05601 | N15: 0 | O15: 0 | P15: =N15+O15 -> 0 | Q15: 0
A16: 0.06263 | B16: 4 | C16: 0 | D16: =B16+C16 -> 4 | E16: =B16/D16*100 -> 100 | G16: 0.06265 | H16: 10 | I16: 0 | J16: =H16+I16 -> 10 | K16: =H16/J16*100 -> 100 | M16: 0.0626 | N16: 0 | O16: 0 | P16: =N16+O16 -> 0 | Q16: 0
A17: 0.06285 | B17: 0 | C17: 0 | D17: =B17+C17 -> 0 | E17: 0 | G17: 0.06287 | H17: 0 | I17: 0 | J17: =H17+I17 -> 0 | K17: 0 | M17: 0.06281 | N17: 0 | O17: 0 | P17: =N17+O17 -> 0 | Q17: 0
A18: 0.06952 | B18: 0 | C18: 0 | D18: =B18+C18 -> 0 | E18: 0 | G18: 0.06954 | H18: 4 | I18: 0 | J18: =H18+I18 -> 4 | K18: =H18/J18*100 -> 100 | M18: 0.06947 | N18: 0 | O18: 0 | P18: =N18+O18 -> 0 | Q18: 0
A19: 0.07619 | B19: 0 | C19: 0 | D19: =B19+C19 -> 0 | E19: 0 | G19: 0.07621 | H19: 0 | I19: 0 | J19: =H19+I19 -> 0 | K19: 0 | M19: 0.07614 | N19: 0 | O19: 0 | P19: =N19+O19 -> 0 | Q19: 0
A20: 0.08148 | B20: 0 | C20: 0 | D20: =B20+C20 -> 0 | E20: 0 | G20: 0.08147 | H20: 0 | I20: 0 | J20: =H20+I20 -> 0 | K20: 0 | M20: 0.08139 | N20: 0 | O20: 0 | P20: =N20+O20 -> 0 | Q20: 0
A21: 0.08823 | B21: 4 | C21: 4 | D21: =B21+C21 -> 8 | E21: =B21/D21*100 -> 50 | G21: 0.08822 | H21: 4 | I21: 0 | J21: =H21+I21 -> 4 | K21: =H21/J21*100 -> 100 | M21: 0.08814 | N21: 0 | O21: 0 | P21: =N21+O21 -> 0 | Q21: 0
A22: 0.09498 | B22: 18 | C22: 0 | D22: =B22+C22 -> 18 | E22: =B22/D22*100 -> 100 | G22: 0.09497 | H22: 4 | I22: 0 | J22: =H22+I22 -> 4 | K22: =H22/J22*100 -> 100 | M22: 0.09489 | N22: 2 | O22: 0 | P22: =N22+O22 -> 2 | Q22: =N22/P22*100 -> 100
A23: 0.10173 | B23: 0 | C23: 0 | D23: =B23+C23 -> 0 | E23: 0 | G23: 0.10172 | H23: 0 | I23: 4 | J23: =H23+I23 -> 4 | K23: =H23/J23*100 -> 0 | M23: 0.10164 | N23: 4 | O23: 0 | P23: =N23+O23 -> 4 | Q23: =N23/P23*100 -> 100
A24: 0.10576 | B24: 8 | C24: 0 | D24: =B24+C24 -> 8 | E24: =B24/D24*100 -> 100 | G24: 0.10574 | H24: 0 | I24: 0 | J24: =H24+I24 -> 0 | K24: 0 | M24: 0.10566 | N24: 0 | O24: 0 | P24: =N24+O24 -> 0 | Q24: 0
A25: 0.11268 | B25: 18 | C25: 7 | D25: =B25+C25 -> 25 | E25: =B25/D25*100 -> 72 | G25: 0.11266 | H25: 10 | I25: 10 | J25: =H25+I25 -> 20 | K25: =H25/J25*100 -> 50 | M25: 0.11258 | N25: 23 | O25: 0 | P25: =N25+O25 -> 23 | Q25: =N25/P25*100 -> 100
A26: 0.1196 | B26: 12 | C26: 0 | D26: =B26+C26 -> 12 | E26: =B26/D26*100 -> 100 | G26: 0.11958 | H26: 13 | I26: 14 | J26: =H26+I26 -> 27 | K26: =H26/J26*100 -> 48.148148 | M26: 0.1195 | N26: 7 | O26: 22 | P26: =N26+O26 -> 29 | Q26: =N26/P26*100 -> 24.137931
A27: 0.12652 | B27: 31 | C27: 4 | D27: =B27+C27 -> 35 | E27: =B27/D27*100 -> 88.571429 | G27: 0.1265 | H27: 20 | I27: 6 | J27: =H27+I27 -> 26 | K27: =H27/J27*100 -> 76.923077 | M27: 0.12642 | N27: 16 | O27: 28 | P27: =N27+O27 -> 44 | Q27: =N27/P27*100 -> 36.363636
A28: 0.13344 | B28: 24 | C28: 5 | D28: =B28+C28 -> 29 | E28: =B28/D28*100 -> 82.758621 | G28: 0.13342 | H28: 11 | I28: 0 | J28: =H28+I28 -> 11 | K28: =H28/J28*100 -> 100 | M28: 0.13334 | N28: 42 | O28: 40 | P28: =N28+O28 -> 82 | Q28: =N28/P28*100 -> 51.219512
A29: 0.14036 | B29: 13 | C29: 26 | D29: =B29+C29 -> 39 | E29: =B29/D29*100 -> 33.333333 | G29: 0.14034 | H29: 19 | I29: 16 | J29: =H29+I29 -> 35 | K29: =H29/J29*100 -> 54.285714 | M29: 0.14026 | N29: 12 | O29: 12 | P29: =N29+O29 -> 24 | Q29: =N29/P29*100 -> 50
A30: 0.14728 | B30: 14 | C30: 22 | D30: =B30+C30 -> 36 | E30: =B30/D30*100 -> 38.888889 | G30: 0.14726 | H30: 22 | I30: 18 | J30: =H30+I30 -> 40 | K30: =H30/J30*100 -> 55 | M30: 0.14718 | N30: 22 | O30: 26 | P30: =N30+O30 -> 48 | Q30: =N30/P30*100 -> 45.833333
A31: 0.1542 | B31: 8 | C31: 15 | D31: =B31+C31 -> 23 | E31: =B31/D31*100 -> 34.782609 | G31: 0.15418 | H31: 41 | I31: 12 | J31: =H31+I31 -> 53 | K31: =H31/J31*100 -> 77.358491 | M31: 0.1541 | N31: 36 | O31: 33 | P31: =N31+O31 -> 69 | Q31: =N31/P31*100 -> 52.173913
A32: 0.16112 | B32: 5 | C32: 23 | D32: =B32+C32 -> 28 | E32: =B32/D32*100 -> 17.857143 | G32: 0.1611 | H32: 11 | I32: 37 | J32: =H32+I32 -> 48 | K32: =H32/J32*100 -> 22.916667 | M32: 0.16102 | N32: 27 | O32: 25 | P32: =N32+O32 -> 52 | Q32: =N32/P32*100 -> 51.923077
A33: 0.16804 | B33: 30 | C33: 21 | D33: =B33+C33 -> 51 | E33: =B33/D33*100 -> 58.823529 | G33: 0.16802 | H33: 44 | I33: 13 | J33: =H33+I33 -> 57 | K33: =H33/J33*100 -> 77.192982 | M33: 0.16794 | N33: 29 | O33: 17 | P33: =N33+O33 -> 46 | Q33: =N33/P33*100 -> 63.043478
A34: 0.17496 | B34: 21 | C34: 19 | D34: =B34+C34 -> 40 | E34: =B34/D34*100 -> 52.5 | G34: 0.17494 | H34: 28 | I34: 4 | J34: =H34+I34 -> 32 | K34: =H34/J34*100 -> 87.5 | M34: 0.17486 | N34: 35 | O34: 15 | P34: =N34+O34 -> 50 | Q34: =N34/P34*100 -> 70
A35: 0.18188 | B35: 25 | C35: 9 | D35: =B35+C35 -> 34 | E35: =B35/D35*100 -> 73.529412 | G35: 0.18186 | H35: 20 | I35: 17 | J35: =H35+I35 -> 37 | K35: =H35/J35*100 -> 54.054054 | M35: 0.18178 | N35: 33 | O35: 10 | P35: =N35+O35 -> 43 | Q35: =N35/P35*100 -> 76.744186
A36: 0.1888 | B36: 0 | C36: 0 | D36: =B36+C36 -> 0 | E36: =B36/D36*100 -> #DIV/0! | G36: 0.18878 | H36: 34 | I36: 0 | J36: =H36+I36 -> 34 | K36: =H36/J36*100 -> 100 | M36: 0.1887 | N36: 19 | O36: 45 | P36: =N36+O36 -> 64 | Q36: =N36/P36*100 -> 29.6875
... A4824: 31.52968 | B4824: 36 | C4824: 346 | D4824: =B4824+C4824 -> 382 | E4824: =B4824/D4824*100 -> 9.4240838 | G4824: 31.48266 | H4824: 34 | I4824: 131 | J4824: =H4824+I4824 -> 165 | K4824: =H4824/J4824*100 -> 20.606061 | M4824: 31.57939 | N4824: 27 | O4824: 455 | P4824: =N4824+O4824 -> 482 | Q4824: =N4824/P4824*100 -> 5.6016598

Sheet All peptides
C2: P1-L38M | D2: P1-L38A | E2: P1-V40A | F2: P1-WT
B3: Run 1 | C3: =AVERAGE('P1-L38M'!E4481:E4825) -> 36.037588 | D3: =AVERAGE('P1-L38A'!E4556:E4752) -> 1.7232317 | E3: =AVERAGE('P1-V40A'!E4591:E4824) -> 4.7675702 | F3: =AVERAGE('P1-WT'!E4500:E4825) -> 5.9629739
B4: Run2 | C4: =AVERAGE('P1-L38M'!K4482:K4825) -> 29.034195 | D4: =AVERAGE('P1-L38A'!K4609:K4814) -> 1.0339497 | E4: =AVERAGE('P1-V40A'!K4598:K4824) -> 18.796424 | F4: =AVERAGE('P1-WT'!K4503:K4825) -> 7.5147025
B5: Run 3 | C5: =AVERAGE('P1-L38M'!Q4482:Q4825) -> 38.837628 | D5: =AVERAGE('P1-L38A'!Q4605:Q4810) -> 2.74444 | E5: =AVERAGE('P1-V40A'!Q4583:Q4824) -> 5.5251561 | F5: =AVERAGE('P1-WT'!Q4511:Q4825) -> 17.361306
B6: Average | C6: =AVERAGE(C3:C5) -> 34.63647 | D6: =AVERAGE(D3:D5) -> 1.8338738 | E6: =AVERAGE(E3:E5) -> 9.6963834 | F6: =AVERAGE(F3:F5) -> 10.279661
B7: Standard Deviation | C7: =_xlfn.STDEV.P(C3:C5) -> 4.1230388 | D7: =_xlfn.STDEV.P(D3:D5) -> 0.70267374 | E7: =_xlfn.STDEV.P(E3:E5) -> 6.4421289 | F7: =_xlfn.STDEV.P(F3:F5) -> 5.0473912
B8: Standard Error | C8: =_xlfn.STDEV.P(C3:C5)/SQRT(COUNT(C3:C5)) -> 2.3804376 | D8: =_xlfn.STDEV.P(D3:D5)/SQRT(COUNT(D3:D5)) -> 0.40568887 | E8: =_xlfn.STDEV.P(E3:E5)/SQRT(COUNT(E3:E5)) -> 3.7193648 | F8: =_xlfn.STDEV.P(F3:F5)/SQRT(COUNT(F3:F5)) -> 2.9141127
